Workbook

Sheet LBO
C2: Leveraged Buyout of EA by Silver Lake, PIF, and Affinity Partners
C3: In Millions, expect per share data
B5: x | C5: GENERAL INPUTS & ASSUMPTIONS | F5: SOURCES & USES
C7: Company Name | D7: Electronic Arts | F7: Sources of Funds | G7: EBITDA Turns | J7: Uses of Funds
C8: Ticker | D8: NASDAQ: EA | F8: Excess Cash | G8: =H8/D12 -> 0.79533981 | H8: =D14-D15 -> 2048 | J8: Buyout of equity | L8: =D31 -> 54198.419
C9: Target share price | D9: 168.32 | F9: Revolver | G9: 0 | H9: =G9*D12 -> 0 | J9: Refinancing of debt | L9: =-D13 -> 1884
C10: Share price closing date | D10: 45925 | F10: Term loan | G10: 7 | H10: =G10*D12 -> 18025 | J10: Transaction and financing fees | L10: =J26+J29 -> 541.3671
F11: Senior note | G11: 0 | H11: =G11*D12 -> 0 | J11: Total Uses | L11: =SUM(L8:L10) -> 56623.786
C12: LTM EBITDA | D12: =Financials!F38 -> 2575 | F12: Sub note | G12: 0 | H12: =G12*D12 -> 0
C13: Gross Debt | D13: =-Financials!F67 -> -1884 | F13: Preferred stock | G13: 0 | H13: =G13*D12 -> 0
C14: Cash | D14: =Financials!F55 -> 2248 | F14: PIF rollover | G14: 2.03 | H14: =G14*D12 -> 5227.25
C15: Minimum cash | D15: 200 | F15: Sponsor equity | G15: =H15/D12 -> 12.16448 | H15: =L11-SUM(H8:H14) -> 31323.536
C16: EV/LTM EBITDA | D16: 31.5 | F16: Total Sources | H16: =SUM(H8:H15) -> 56623.786
C19: ENTRY VALUATION | H19: FEES
I20: % fees | J20: Fee | K20: Term | L20: Amortization
C21: Valuation Approach: | D21: 2 | E21: 1 | F21: 2 | H21: Financing Fees
D22: =CHOOSE($D$21,E22,F22) -> Offer/share | E22: EBITDA Multiple | F22: Offer/share | H22: Revolver | I22: 0.01 | J22: =I22*H9 -> 0 | K22: 5 | L22: =IFERROR(J22/K22,"NM") -> 0
H23: Term loan | I23: 0.015 | J23: =I23*H10 -> 270.375 | K23: 7 | L23: =IFERROR(J23/K23,"NM") -> 38.625
C24: LTM EBITDA | D24: =D12 -> 2575 | E24: =D12 -> 2575 | F24: =D12 -> 2575 | H24: Senior note | I24: 0.015 | J24: =I24*H11 -> 0 | L24: =IFERROR(J24/K24,"NM") -> NM
C25: EV/LTM EBITDA | D25: =CHOOSE($D$21,E25,F25) -> 20.906571 | E25: 22 | F25: =F26/F24 -> 20.906571 | H25: Sub note | I25: 0 | J25: =I25*H12 -> 0 | L25: =IFERROR(J25/K25,"NM") -> NM
C26: Enterprise Value | D26: =D24*D25 -> 53834.419 | E26: =E24*E25 -> 56650 | F26: =F31-SUM(F28:F29) -> 53834.419 | H26: Financing fees | J26: =SUM(J22:J25) -> 270.375 | L26: =SUM(L22:L23) -> 38.625
C28: Less: Gross debt | D28: =$D$13 -> -1884 | E28: =$D$13 -> -1884 | F28: =$D$13 -> -1884 | I28: % of Offer Value | J28: Fee
C29: Plus: Cash | D29: =$D$14 -> 2248 | E29: =$D$14 -> 2248 | F29: =$D$14 -> 2248 | H29: Transaction fees | I29: 0.005 | J29: =I29*D31 -> 270.9921
C31: Offer Value | D31: =D26+SUM(D28:D29) -> 54198.419 | E31: =E26+SUM(E28:E29) -> 57014 | F31: =F34*F32 -> 54198.419
C32: Diluted shares | D32: =DCF!$I$72 -> 258.08771 | E32: =DCF!$I$72 -> 258.08771 | F32: =DCF!$I$72 -> 258.08771
C34: Offer Value per share | D34: =D31/D32 -> 210 | E34: =E31/E32 -> 220.90939 | F34: 210
C35: Offer premium/discount | D35: =D34/$D$9-1 -> 0.24762357 | E35: =E34/$D$9-1 -> 0.31243699 | F35: =F34/$D$9-1 -> 0.24762357
B38: x | C38: EXIT VALUATION
G39: Step | H39: Assumed exit at March 31, 2030
C40: Exit EBITDA Multiple | G40: 5 | H40: =D16-10 -> 21.5 | I40: =H40+$G$40 -> 26.5 | J40: =I40+$G$40 -> 31.5 | K40: =J40+$G$40 -> 36.5 | L40: =K40+$G$40 -> 41.5
C41: Exit EBITDA | H41: =Financials!$K$38 -> 3506.0166 | I41: =Financials!$K$38 -> 3506.0166 | J41: =Financials!$K$38 -> 3506.0166 | K41: =Financials!$K$38 -> 3506.0166 | L41: =Financials!$K$38 -> 3506.0166
C42: Enterprise value | H42: =H41*H40 -> 75379.358 | I42: =I41*I40 -> 92909.441 | J42: =J41*J40 -> 110439.52 | K42: =K41*K40 -> 127969.61 | L42: =L41*L40 -> 145499.69
C44: Net Debt
C45: Revolver | H45: =Financials!$K$212 -> 0 | I45: =Financials!$K$212 -> 0 | J45: =Financials!$K$212 -> 0 | K45: =Financials!$K$212 -> 0 | L45: =Financials!$K$212 -> 0
C46: Term Loan | H46: =Financials!$K$218 -> 10206.373 | I46: =Financials!$K$218 -> 10206.373 | J46: =Financials!$K$218 -> 10206.373 | K46: =Financials!$K$218 -> 10206.373 | L46: =Financials!$K$218 -> 10206.373
C47: Senior Note | H47: =Financials!$K$225 -> 0 | I47: =Financials!$K$225 -> 0 | J47: =Financials!$K$225 -> 0 | K47: =Financials!$K$225 -> 0 | L47: =Financials!$K$225 -> 0
C48: Sub Note | H48: =Financials!$K$232 -> 0 | I48: =Financials!$K$232 -> 0 | J48: =Financials!$K$232 -> 0 | K48: =Financials!$K$232 -> 0 | L48: =Financials!$K$232 -> 0
C49: Pref. stock | H49: =Financials!$K$238 -> 0 | I49: =Financials!$K$238 -> 0 | J49: =Financials!$K$238 -> 0 | K49: =Financials!$K$238 -> 0 | L49: =Financials!$K$238 -> 0
C50: Cash | H50: =-Financials!$K$199 -> -200 | I50: =-Financials!$K$199 -> -200 | J50: =-Financials!$K$199 -> -200 | K50: =-Financials!$K$199 -> -200 | L50: =-Financials!$K$199 -> -200
C52: Equity value | E52: Initial Investment | F52: % Ownership | G52: Fully Diluted | H52: =H42-SUM(H45:H50) -> 65372.985 | I52: =I42-SUM(I45:I50) -> 82903.068 | J52: =J42-SUM(J45:J50) -> 100433.15 | K52: =K42-SUM(K45:K50) -> 117963.23 | L52: =L42-SUM(L45:L50) -> 135493.32
...

Sheet Financials
C2: Financial Statement Model
C3: In Millions, expect per share data
C5: Circ Breaker (Off = 1, On = 0) | D5: 1
C6: Latest Fiscal Year End | D6: 45747
C7: Shares outstanding (millions) | D7: 250.25371
B9: x | C9: INCOME STATEMENT
C10: Fiscal Year | D10: 2023 | E10: 2024 | F10: 2025 | G10: 2026 | H10: 2027 | I10: 2028 | J10: 2029 | K10: 2030
C11: End Date | D11: 45016 | E11: =EOMONTH(D11,12) -> 45382 | F11: =EOMONTH(E11,12) -> 45747 | G11: =EOMONTH(F11,12) -> 46112 | H11: =EOMONTH(G11,12) -> 46477 | I11: =EOMONTH(H11,12) -> 46843 | J11: =EOMONTH(I11,12) -> 47208 | K11: =EOMONTH(J11,12) -> 47573
C13: Revenue | D13: 7426 | E13: 7562 | F13: 7463 | G13: 8092.11 | H13: 8412.18 | I13: 8872.86 | J13: 9809.67 | K13: 10448
C14: Cost of revenue | D14: -1792 | E14: -1710 | F14: -1543 | G14: =G15-G13 -> -1818.5622 | H14: =H15-H13 -> -1890.4924 | I14: =I15-I13 -> -1994.0223 | J14: =J15-J13 -> -2204.5542 | K14: =K15-K13 -> -2348.0078
C15: Gross profit | D15: =SUM(D13:D14) -> 5634 | E15: =SUM(E13:E14) -> 5852 | F15: =SUM(F13:F14) -> 5920 | G15: =G13*G42 -> 6273.5478 | H15: =H13*H42 -> 6521.6876 | I15: =I13*I42 -> 6878.8377 | J15: =J13*J42 -> 7605.1158 | K15: =K13*K42 -> 8099.9922
C17: Research and development | D17: -2328 | E17: -2420 | F17: -2569 | G17: =-G44*G13 -> -2637.3423 | H17: =-H44*H13 -> -2741.658 | I17: =-I44*I13 -> -2891.8006 | J17: =-J44*J13 -> -3197.1213 | K17: =-K44*K13 -> -3405.1628
C18: Marketing and sales | D18: -978 | E18: -1019 | F18: -962 | G18: =-G45*G13 -> -1066.418 | H18: =-H45*H13 -> -1108.5984 | I18: =-I45*I13 -> -1169.3091 | J18: =-J45*J13 -> -1292.7665 | K18: =-K45*K13 -> -1376.8887
C19: General and administrative | D19: -727 | E19: -691 | F19: -745 | G19: =-G46*G13 -> -779.81782 | H19: =-H46*H13 -> -810.66222 | I19: =-I46*I13 -> -855.05688 | J19: =-J46*J13 -> -945.33508 | K19: =-K46*K13 -> -1006.8495
C20: Amortization and impairment of intangible assets | D20: -158 | E20: -142 | F20: -67 | G20: =G189 -> -72.647912 | H20: =H189 -> -75.52138 | I20: =I189 -> -79.657191 | J20: =J189 -> -88.067518 | K20: =K189 -> -93.798204
C21: Deal-related D&A | G21: =-('Pro Forma'!$D$15+'Pro Forma'!$D$22) -> -38.09 | H21: =-('Pro Forma'!$D$15+'Pro Forma'!$D$22) -> -38.09 | I21: =-('Pro Forma'!$D$15+'Pro Forma'!$D$22) -> -38.09 | J21: =-('Pro Forma'!$D$15+'Pro Forma'!$D$22) -> -38.09 | K21: =-('Pro Forma'!$D$15+'Pro Forma'!$D$22) -> -38.09
C22: Restructuring | D22: -111 | E22: -62 | F22: -57 | G22: =F22 -> -57 | H22: =G22 -> -57 | I22: =H22 -> -57 | J22: =I22 -> -57 | K22: =J22 -> -57
C23: Operating income (EBIT) | D23: =D15+SUM(D17:D22) -> 1332 | E23: =E15+SUM(E17:E22) -> 1518 | F23: =F15+SUM(F17:F22) -> 1520 | G23: =G15+SUM(G17:G22) -> 1622.2318 | H23: =H15+SUM(H17:H22) -> 1690.1576 | I23: =I15+SUM(I17:I22) -> 1787.9239 | J23: =J15+SUM(J17:J22) -> 1986.7354 | K23: =K15+SUM(K17:K22) -> 2122.2029
C25: Interest income | D25: 49 | E25: 126 | F25: 125 | G25: =G201 -> 9.0744102 | H25: =H201 -> 9.0744102 | I25: =I201 -> 9.0744102 | J25: =J201 -> 9.0744102 | K25: =K201 -> 9.0744102
C26: Interest expense | D26: -58 | E26: -58 | F26: -58 | G26: =-SUM(G253:G257)+G243 -> -1286.196 | H26: =-SUM(H253:H257)+H243 -> -1178.2191 | I26: =-SUM(I253:I257)+I243 -> -1057.9559 | J26: =-SUM(J253:J257)+J243 -> -958.20671 | K26: =-SUM(K253:K257)+K243 -> -840.86202
C27: Other income (expense) | D27: 3 | E27: 3 | F27: 18 | G27: =F27 -> 18 | H27: =G27 -> 18 | I27: =H27 -> 18 | J27: =I27 -> 18 | K27: =J27 -> 18
C28: Income before provision for income taxes | D28: =D23+SUM(D25:D27) -> 1326 | E28: =E23+SUM(E25:E27) -> 1589 | F28: =F23+SUM(F25:F27) -> 1605 | G28: =G23+SUM(G25:G27) -> 363.11025 | H28: =H23+SUM(H25:H27) -> 539.0129 | I28: =I23+SUM(I25:I27) -> 757.04246 | J28: =J23+SUM(J25:J27) -> 1055.6031 | K28: =K23+SUM(K25:K27) -> 1308.4153
C30: Provision for income taxes | D30: -524 | E30: -316 | F30: -484 | G30: =-G48*G28 -> -108.40031 | H30: =-H48*H28 -> -160.91301 | I30: =-I48*I28 -> -226.00198 | J30: =-J48*J28 -> -315.13212 | K30: =-K48*K28 -> -390.60484
C31: Net income | D31: =D28+D30 -> 802 | E31: =E28+E30 -> 1273 | F31: =F28+F30 -> 1121 | G31: =G28+G30 -> 254.70994 | H31: =H28+H30 -> 378.09988 | I31: =I28+I30 -> 531.04048 | J31: =J28+J30 -> 740.47099 | K31: =K28+K30 -> 917.81048
C33: EBIT (GAAP) | D33: =D23 -> 1332 | E33: =E23 -> 1518 | F33: =F23 -> 1520 | G33: =G23 -> 1622.2318 | H33: =H23 -> 1690.1576 | I33: =I23 -> 1787.9239 | J33: =J23 -> 1986.7354 | K33: =K23 -> 2122.2029
C34: Depreciation and amortization | D34: 536 | E34: 404 | F34: 356 | G34: =G181-G189 -> 320.17385 | H34: =H181-H189 -> 293.02888 | I34: =I181-I189 -> 301.81066 | J34: =J181-J189 -> 339.57686 | K34: =K181-K189 -> 389.94092
C35: Stock-based compensation | D35: 548 | E35: 584 | F35: 642 | G35: =F35*(1+G41) -> 696.1188 | H35: =G35*(1+H41) -> 723.65263 | I35: =H35*(1+I41) -> 763.28234 | J35: =I35*(1+J41) -> 843.87085 | K35: =J35*(1+K41) -> 898.7828
C36: Deal-related D&A | G36: =-G21 -> 38.09 | H36: =-H21 -> 38.09 | I36: =-I21 -> 38.09 | J36: =-J21 -> 38.09 | K36: =-K21 -> 38.09
C37: Restructuring | D37: =-D22 -> 111 | E37: =-E22 -> 62 | F37: =-F22 -> 57 | G37: =-G22 -> 57 | H37: =-H22 -> 57 | I37: =-I22 -> 57 | J37: =-J22 -> 57 | K37: =-K22 -> 57
C38: EBITDA | D38: =SUM(D33:D37) -> 2527 | E38: =SUM(E33:E37) -> 2568 | F38: =SUM(F33:F37) -> 2575 | G38: =SUM(G33:G37) -> 2733.6145 | H38: =SUM(H33:H37) -> 2801.9291 | I38: =SUM(I33:I37) -> 2948.107 | J38: =SUM(J33:J37) -> 3265.2731 | K38: =SUM(K33:K37) -> 3506.0166
C40: Growth rates and margins
C41: Revenue growth % | E41: =E13/D13-1 -> 0.018314032 | F41: =F13/E13-1 -> -0.013091775 | G41: =G13/F13-1 -> 0.0842972 | H41: =H13/G13-1 -> 0.039553343 | I41: =I13/H13-1 -> 0.05476345 | J41: =J13/I13-1 -> 0.10558151 | K41: =K13/J13-1 -> 0.065071506
C42: Gross margin % | D42: =D15/D13 -> 0.7586857 | E42: =E15/E13 -> 0.77386935 | F42: =F15/F13 -> 0.79324668 | G42: =AVERAGE(D42:F42) -> 0.77526724 | H42: =G42 -> 0.77526724 | I42: =H42 -> 0.77526724 | J42: =I42 -> 0.77526724 | K42: =J42 -> 0.77526724
C44: Research and development % of sales | D44: =-D17/D13 -> 0.31349313 | E44: =-E17/E13 -> 0.32002116 | F44: =-F17/F13 -> 0.34423154 | G44: =AVERAGE(D44:F44) -> 0.32591528 | H44: =G44 -> 0.32591528 | I44: =H44 -> 0.32591528 | J44: =I44 -> 0.32591528 | K44: =J44 -> 0.32591528
C45: Marketing and sales % of sales | D45: =-D18/D13 -> 0.13169943 | E45: =-E18/E13 -> 0.13475271 | F45: =-F18/F13 -> 0.12890259 | G45: =AVERAGE(D45:F45) -> 0.13178491 | H45: =G45 -> 0.13178491 | I45: =H45 -> 0.13178491 | J45: =I45 -> 0.13178491 | K45: =J45 -> 0.13178491
C46: General and administrative % of sales | D46: =-D19/D13 -> 0.097899273 | E46: =-E19/E13 -> 0.091377942 | F46: =-F19/F13 -> 0.099825807 | G46: =AVERAGE(D46:F46) -> 0.096367674 | H46: =G46 -> 0.096367674 | I46: =H46 -> 0.096367674 | J46: =I46 -> 0.096367674 | K46: =J46 -> 0.096367674
C48: Tax rate | D48: =-D30/D28 -> 0.39517345 | E48: =-E30/E28 -> 0.19886721 | F48: =-F30/F28 -> 0.30155763 | G48: =AVERAGE(D48:F48) -> 0.29853277 | H48: =G48 -> 0.29853277 | I48: =H48 -> 0.29853277 | J48: =I48 -> 0.29853277 | K48: =J48 -> 0.29853277
B51: x | C51: HISTORICAL BALANCE SHEET
C52: Fiscal Year | D52: 2023 | E52: 2024 | F52: 2025
C53: End Date | D53: 45016 | E53: =EOMONTH(D53,12) -> 45382 | F53: =EOMONTH(E53,12) -> 45747
...

Sheet Pro Forma
C2: Purchase Price Allocation & Pro Forma Adjustments
C3: In Millions, expect per share data
C5: Tax Structure | D5: Stock Sale
C6: LBO / Recap | D6: LBO
B8: x | C8: Purchase Price Allocation
C10: Asset Write-ups | F10: Purchase Price Allocation
C11: Book value of PP&E | D11: =E41 -> 586 | F11: Book Value of Total Assets | H11: =E46 -> 12368
C12: % Write-up | D12: 0.2 | F12: Plus: PP&E write ups | H12: =D13 -> 117.2
C13: Asset write-up | D13: =IF($D$6="LBO",D11*D12,0) -> 117.2 | F13: Plus: Intangible asset write ups | H13: =D20 -> 87.9
C14: Useful life | D14: =Financials!D172 -> 5 | F14: Fair Market Value of Assets | H14: =SUM(H11:H13) -> 12573.1
C15: Incremental depreciation expense | D15: =D13/D14 -> 23.44
C16: Incremental deferred tax liabilities | D16: =IF($D$5="Stock Sale",D13*Financials!G48,0) -> 34.98804 | F16: Book Value of Total Liabilities | H16: =E53 -> 5982
F17: Plus: New deferred tax liabilities created | H17: =D16+D23 -> 61.22907
C18: Book value of intangible assets | D18: =E43 -> 293 | F18: Fair Market Value of Liabilities | H18: =SUM(H16:H17) -> 6043.2291
C19: % Write-up | D19: 0.3
C20: Asset write-up | D20: =IF($D$6="LBO",D18*D19,0) -> 87.9 | F20: Equity fair market value | H20: =H14-H18 -> 6529.8709
C21: Useful life | D21: 6 | F21: Offer value | H21: =LBO!D31 -> 54198.419
C22: Incremental amortization expense | D22: =D20/D21 -> 14.65 | F22: Goodwill created in transaction | H22: =H21-H20 -> 47668.548
C23: Incremental deferred tax liabilities | D23: =IF($D$5="Stock Sale",D20*Financials!G48,0) -> 26.24103
C26: Deal-related Accounting Adjustments
E27: 2026 | F27: 2027 | G27: 2028 | H27: 2029 | I27: 2030
E28: 46112 | F28: =EOMONTH(E28,12) -> 46477 | G28: =EOMONTH(F28,12) -> 46843 | H28: =EOMONTH(G28,12) -> 47208 | I28: =EOMONTH(H28,12) -> 47573
C29: PPE | E29: =D13-D15 -> 93.76 | F29: =E29-$D$15 -> 70.32 | G29: =F29-$D$15 -> 46.88 | H29: =G29-$D$15 -> 23.44 | I29: =H29-$D$15 -> 0
C30: Intangible assets | E30: =D20-D22 -> 73.25 | F30: =E30-$D$22 -> 58.6 | G30: =F30-$D$22 -> 43.95 | H30: =G30-$D$22 -> 29.3 | I30: =H30-$D$22 -> 14.65
C31: Deferred tax liabilities | D31: =IF($D$5="Stock Sale",(D15+D22)*Financials!G48,0) -> 11.371113 | E31: =H17-D31 -> 49.857957 | F31: =E31-$D$31 -> 38.486844 | G31: =F31-$D$31 -> 27.115731 | H31: =G31-$D$31 -> 15.744618 | I31: =H31-$D$31 -> 4.373505
B34: x | C34: PRO FORMA BALANCE SHEET ADJUSTMENTS
C35: Fiscal Year | E35: 2025 | F35: Pro Forma Adjustments | I35: Pro Forma
C36: End Date | E36: 45747 | F36: Uses of Funds | G36: Sources of Funds | H36: Accounting | I36: =E36 -> 45747
C38: Cash and cash equivalents | E38: =Financials!F55 -> 2248 | F38: =SUM(F50,F55) -> -51396.536 | G38: =SUM(G50,G55,G56) -> 49348.536 | I38: =SUM(E38:H38) -> 200
C39: Receivables | E39: =Financials!F56 -> 679 | I39: =SUM(E39:H39) -> 679
C40: Other current assets | E40: =Financials!F57 -> 349 | I40: =SUM(E40:H40) -> 349
C41: Property and equipment | E41: =Financials!F58 -> 586 | H41: =D13 -> 117.2 | I41: =SUM(E41:H41) -> 703.2
C42: Goodwill | E42: =Financials!F59 -> 5376 | H42: =H22 -> 47668.548 | I42: =SUM(E42:H42) -> 53044.548
C43: Acquisition-related intangibles | E43: =Financials!F60 -> 293 | H43: =D20 -> 87.9 | I43: =SUM(E43:H43) -> 380.9
C44: Deferred income taxes | E44: =Financials!F61 -> 2420 | I44: =SUM(E44:H44) -> 2420
C45: Other assets | E45: =Financials!F62 -> 417 | I45: =SUM(E45:H45) -> 417
C46: Total assets | E46: =SUM(E38:E45) -> 12368 | I46: =SUM(I38:I45) -> 58193.648
C48: Accounts payable, accrued and other current liabilities | E48: =Financials!F65 -> 1359 | I48: =SUM(E48:H48) -> 1359
C49: Deferred revenue | E49: =Financials!F66 -> 1700 | I49: =SUM(E49:H49) -> 1700
C50: Debt | E50: =Financials!F67 -> 1884 | F50: =-LBO!L9-LBO!J26 -> -2154.375 | G50: =SUM(LBO!H9:H12) -> 18025 | I50: =SUM(E50:H50) -> 17754.625
...

Sheet WACC
C2: WACC Analysis
C3: In Millions, expect per share data
C5: INPUTS | F5: BETA CALCULATION
H6: 5-year
C7: Tax rate (5-year average) | D7: 0.20954 | F7: Company Name | G7: Ticker | H7: average tax rate | I7: Levered Beta | J7: Total Debt | K7: Market cap | L7: Unlevered Beta
C8: Risk-free rate | D8: 0.0431 | F8: Roblox Corporation | G8: NYSE: RBLX | H8: 0.088375 | I8: 1.67 | J8: 1764.4 | K8: 79317.6 | L8: =I8/(1+(1-H8)*(J8/K8)) -> 1.6368074
C9: Market risk premium | D9: 0.0418 | F9: Take-Two Interactive Software | G9: NASDAQ: TTWO | H9: 0.14514 | I9: 0.97 | J9: 3511.7 | K9: 42868.7 | L9: =I9/(1+(1-H9)*(J9/K9)) -> 0.90651828
F10: Playtika Holding Corp | G10: NASDAQ: PLTK | H10: 0.3184 | I10: 0.88 | J10: 2541.5 | K10: 1571.9 | L10: =I10/(1+(1-H10)*(J10/K10)) -> 0.41864224
C11: WACC | F11: Playstudios | G11: NASDAQ: MYPS | H11: 0.32333333 | I11: 0.95 | J11: 8.6 | K11: 95.5 | L11: =I11/(1+(1-H11)*(J11/K11)) -> 0.89543621
F12: Average | L12: =AVERAGE(L8:L11) -> 0.96435103
C13: Market risk premium | D13: =D9 -> 0.0418 | F13: EA Avg Tax Rate | L13: =D7 -> 0.20954
C14: Levered Beta | D14: =L16 -> 0.99741028 | F14: Total Debt | L14: =SUM(DCF!I52:I56) -> 1884
C15: Adjusted market risk premium | D15: =D13*D14 -> 0.04169175 | F15: Market cap | L15: =DCF!I72*DCF!D8 -> 43441.324
C16: Add: risk-free rate | D16: =D8 -> 0.0431 | F16: EA Levered Beta | L16: =L12*(1+(1-L13)*(L14/L15)) -> 0.99741028
C17: Cost of Equity | D17: =D15+D16 -> 0.08479175
C18: Equity to total capitalization | D18: =L15/(L15+L14) -> 0.95843383 | F18: WACC Sensitivity
C19: Cost of equity portion | D19: =D17*D18 -> 0.081267281
F20: Pre-tax cost of debt
C21: Cost of debt | D21: =-Financials!F26/Financials!F67 -> 0.030785563 | F21: =D27 -> 0.082278784 | G21: 0.005 | H21: =G21+$N$25 -> 0.015 | I21: =H21+$N$25 -> 0.025 | J21: =I21+$N$25 -> 0.035 | K21: =J21+$N$25 -> 0.045 | L21: =K21+$N$25 -> 0.055
C22: Tax rate | D22: =D7 -> 0.20954 | F22: 0.01 | G22: 0.081306804 | H22: 0.08138585 | I22: 0.081464896 | J22: 0.081543942 | K22: 0.081622988 | L22: 0.081702034
C23: After-tax cost of debt | D23: =D21*(1-D22) -> 0.024334756 | F23: =F22+$N$26 -> 0.025 | G23: 0.081366089 | H23: 0.081563704 | I23: 0.081761319 | J23: 0.081958934 | K23: 0.082156549 | L23: 0.082354164
C24: Debt to total capitalization | D24: =L14/(L15+L14) -> 0.041566168 | F24: =F23+$N$26 -> 0.04 | G24: 0.081425373 | H24: 0.081741557 | I24: 0.082057741 | J24: 0.082373925 | K24: 0.082690109 | L24: 0.083006293
C25: Cost of debt portion | D25: =D23*D24 -> 0.0010115025 | F25: =F24+$N$26 -> 0.055 | G25: 0.081484658 | H25: 0.081919411 | I25: 0.082354164 | J25: 0.082788917 | K25: 0.08322367 | L25: 0.083658423 | N25: 0.01 | O25: Pre-tax cost of debt step
F26: =F25+$N$26 -> 0.07 | G26: 0.081543942 | H26: 0.082097264 | I26: 0.082650586 | J26: 0.083203908 | K26: 0.08375723 | L26: 0.084310552 | N26: 0.015 | O26: Debt to total cap
C27: WACC | D27: =D19+D25 -> 0.082278784 | F27: =F26+$N$26 -> 0.085 | G27: 0.081603227 | H27: 0.082275118 | I27: 0.082947009 | J27: 0.0836189 | K27: 0.084290791 | L27: 0.084962682 | N27: 0.035 | O27: Equity to total cap
N28: 0.01 | O28: Cost of equity step
F29: Cost of Equity
F30: =D27 -> 0.082278784 | G30: 0.06 | H30: =G30+$N$28 -> 0.07 | I30: =H30+$N$28 -> 0.08 | J30: =I30+$N$28 -> 0.09 | K30: =J30+$N$28 -> 0.1 | L30: =K30+$N$28 -> 0.11
F31: 0.8 | G31: 0.049011503 | H31: 0.057011503 | I31: 0.065011503 | J31: 0.073011503 | K31: 0.081011503 | L31: 0.089011503
F32: =F31+$N$27 -> 0.835 | G32: 0.051111503 | H32: 0.059461503 | I32: 0.067811503 | J32: 0.076161503 | K32: 0.084511503 | L32: 0.092861503
F33: =F32+$N$27 -> 0.87 | G33: 0.053211503 | H33: 0.061911503 | I33: 0.070611503 | J33: 0.079311503 | K33: 0.088011503 | L33: 0.096711503
F34: =F33+$N$27 -> 0.905 | G34: 0.055311503 | H34: 0.064361503 | I34: 0.073411503 | J34: 0.082461503 | K34: 0.091511503 | L34: 0.1005615
F35: =F34+$N$27 -> 0.94 | G35: 0.057411503 | H35: 0.066811503 | I35: 0.076211503 | J35: 0.085611503 | K35: 0.095011503 | L35: 0.1044115
F36: =F35+$N$27 -> 0.975 | G36: 0.059511503 | H36: 0.069261503 | I36: 0.079011503 | J36: 0.088761503 | K36: 0.098511503 | L36: 0.1082615

Sheet DCF
C2: Discounted Cash Flow Model
C3: In Millions, expect per share data
C5: Most recent fiscal year end | D5: =Financials!D6 -> 45747 | F5: Discount Rate (WACC) | H5: =WACC!D27 -> 0.082278784
C6: End of first fiscal year | D6: =E12 -> 46112 | F6: Midyear Convention | H6: 1
C7: Valuation date | D7: =LBO!D10 -> 45925
C8: Share price | D8: =LBO!D9 -> 168.32
C9: Potion of first year cash flows | D9: =YEARFRAC(D7,D6) -> 0.51666667
B11: x | C11: Fiscal Year | E11: 2026 | F11: 2027 | G11: 2028 | H11: 2029 | I11: 2030
C12: End Date | E12: 46112 | F12: =EOMONTH(E12,12) -> 46477 | G12: =EOMONTH(F12,12) -> 46843 | H12: =EOMONTH(G12,12) -> 47208 | I12: =EOMONTH(H12,12) -> 47573
C14: Revenue | E14: =Financials!G13 -> 8092.11 | F14: =Financials!H13 -> 8412.18 | G14: =Financials!I13 -> 8872.86 | H14: =Financials!J13 -> 9809.67 | I14: =Financials!K13 -> 10448
C15: Cost of revenue | E15: =Financials!G14 -> -1818.5622 | F15: =Financials!H14 -> -1890.4924 | G15: =Financials!I14 -> -1994.0223 | H15: =Financials!J14 -> -2204.5542 | I15: =Financials!K14 -> -2348.0078
C16: Gross profit | E16: =SUM(E14:E15) -> 6273.5478 | F16: =SUM(F14:F15) -> 6521.6876 | G16: =SUM(G14:G15) -> 6878.8377 | H16: =SUM(H14:H15) -> 7605.1158 | I16: =SUM(I14:I15) -> 8099.9922
C18: Research and development | E18: =Financials!G17 -> -2637.3423 | F18: =Financials!H17 -> -2741.658 | G18: =Financials!I17 -> -2891.8006 | H18: =Financials!J17 -> -3197.1213 | I18: =Financials!K17 -> -3405.1628
C19: Marketing and sales | E19: =Financials!G18 -> -1066.418 | F19: =Financials!H18 -> -1108.5984 | G19: =Financials!I18 -> -1169.3091 | H19: =Financials!J18 -> -1292.7665 | I19: =Financials!K18 -> -1376.8887
C20: General and administrative | E20: =Financials!G19 -> -779.81782 | F20: =Financials!H19 -> -810.66222 | G20: =Financials!I19 -> -855.05688 | H20: =Financials!J19 -> -945.33508 | I20: =Financials!K19 -> -1006.8495
C21: Amortization and impairment of intangible assets | E21: =Financials!G20 -> -72.647912 | F21: =Financials!H20 -> -75.52138 | G21: =Financials!I20 -> -79.657191 | H21: =Financials!J20 -> -88.067518 | I21: =Financials!K20 -> -93.798204
C22: Deal-related D&A | E22: =Financials!G21 -> -38.09 | F22: =Financials!H21 -> -38.09 | G22: =Financials!I21 -> -38.09 | H22: =Financials!J21 -> -38.09 | I22: =Financials!K21 -> -38.09
C23: Restructuring | E23: =Financials!G22 -> -57 | F23: =Financials!H22 -> -57 | G23: =Financials!I22 -> -57 | H23: =Financials!J22 -> -57 | I23: =Financials!K22 -> -57
C24: Operating income (EBIT) | E24: =E16+SUM(E18:E23) -> 1622.2318 | F24: =F16+SUM(F18:F23) -> 1690.1576 | G24: =G16+SUM(G18:G23) -> 1787.9239 | H24: =H16+SUM(H18:H23) -> 1986.7354 | I24: =I16+SUM(I18:I23) -> 2122.2029
C25: Tax expense | E25: =E24*-Financials!G48 -> -484.28935 | F25: =F24*-Financials!H48 -> -504.56743 | G25: =G24*-Financials!I48 -> -533.75388 | H25: =H24*-Financials!J48 -> -593.10562 | I25: =I24*-Financials!K48 -> -633.54711
C26: NOPAT | E26: =SUM(E24:E25) -> 1137.9425 | F26: =SUM(F24:F25) -> 1185.5902 | G26: =SUM(G24:G25) -> 1254.1701 | H26: =SUM(H24:H25) -> 1393.6298 | I26: =SUM(I24:I25) -> 1488.6558
C28: Non cash Add Back
C29: Depreciation and amortization | E29: =Financials!G85 -> 320.17385 | F29: =Financials!H85 -> 293.02888 | G29: =Financials!I85 -> 301.81066 | H29: =Financials!J85 -> 339.57686 | I29: =Financials!K85 -> 389.94092
C30: Deal-related D&A | E30: =Financials!G36 -> 38.09 | F30: =Financials!H36 -> 38.09 | G30: =Financials!I36 -> 38.09 | H30: =Financials!J36 -> 38.09 | I30: =Financials!K36 -> 38.09
C32: Net Working Capital Adjustments
C33: (Increase)/Decrease in receivables | E33: =Financials!G88 -> -57.237798 | F33: =Financials!H88 -> -29.120666 | G33: =Financials!I88 -> -41.91367 | H33: =Financials!J88 -> -85.233015 | I33: =Financials!K88 -> -58.076654
C34: (Increase)/Decrease in other current assets | E34: =Financials!G89 -> -29.419723 | F34: =Financials!H89 -> -14.967765 | G34: =Financials!I89 -> -21.543256 | H34: =Financials!J89 -> -43.809016 | I34: =Financials!K89 -> -29.850887
C35: Increase/(Decrease) in A/P, accured and other current liabilities | E35: =Financials!G90 -> 242.70189 | F35: =Financials!H90 -> 63.352664 | G35: =Financials!I90 -> 91.184132 | H35: =Financials!J90 -> 185.42634 | I35: =Financials!K90 -> 126.34707
C36: Increase/(Decrease) in deferred revenue | E36: =Financials!G92 -> 143.30524 | F36: =Financials!H92 -> 72.908884 | G36: =Financials!I92 -> 104.9385 | H36: =Financials!J92 -> 213.39636 | I36: =Financials!K92 -> 145.40547
C38: Capital Expenditures
C39: Capital Expenditures | E39: =Financials!G98 -> -239.62968 | F39: =Financials!H98 -> -249.10784 | G39: =Financials!I98 -> -262.74984 | H39: =Financials!J98 -> -290.49137 | I39: =Financials!K98 -> -309.39408
C40: Unlevered Free Cash Flow | E40: =E26+SUM(E29:E39) -> 1555.9262 | F40: =F26+SUM(F29:F39) -> 1359.7744 | G40: =G26+SUM(G29:G39) -> 1463.9866 | H40: =H26+SUM(H29:H39) -> 1750.586 | I40: =I26+SUM(I29:I39) -> 1791.1177
C42: Fiscal Year | D42: Val Date | E42: 1 | F42: 2 | G42: 3 | H42: 4 | I42: 5
C43: End Date | D43: =D7 -> 45925 | E43: =IF($H$6=0,E12,AVERAGE(D43,E12)) -> 46018.5 | F43: =IF($H$6=0,F12,AVERAGE(F12,E12)) -> 46294.5 | G43: =IF($H$6=0,G12,AVERAGE(G12,F12)) -> 46660 | H43: =IF($H$6=0,H12,AVERAGE(H12,G12)) -> 47025.5 | I43: =IF($H$6=0,I12,AVERAGE(I12,H12)) -> 47390.5
C45: Unlevered Free Cash Flow Stub Adjusted | E45: =E40*D9 -> 803.89522 | F45: =F40 -> 1359.7744 | G45: =G40 -> 1463.9866 | H45: =H40 -> 1750.586 | I45: =I40 -> 1791.1177
C46: PV Factor | E46: =1/(1+$H$5)^((E43-$D$43)/365) -> 0.97994914 | F46: =1/(1+$H$5)^((F43-$D$43)/365) -> 0.92307608 | G46: =1/(1+$H$5)^((G43-$D$43)/365) -> 0.85280809 | H46: =1/(1+$H$5)^((H43-$D$43)/365) -> 0.78788916 | I46: =1/(1+$H$5)^((I43-$D$43)/365) -> 0.72799095
C47: PV of Unlevered Free Cash Flow | E47: =E45*E46 -> 787.77643 | F47: =F45*F46 -> 1255.1752 | G47: =G45*G46 -> 1248.4996 | H47: =H45*H46 -> 1379.2677 | I47: =I45*I46 -> 1303.9174
B50: x | C50: Terminal Value - Gordon Growth | F50: Net Debt
C51: Long-term growth rate | D51: 0.035 | F51: Gross debt and equivalents
C52: 2030 FCF x (1+g) | D52: =I40*(1+D51) -> 1853.8068 | F52: Debt | I52: =Financials!F67 -> 1884
...
